<?xml version="1.0"?>
<robot xmlns:xacro="http://www.ros.org/wiki/xacro" name="arm">
    <!--this is for the gazebo part -->
    <xacro:include filename="$(find turtlefied_pkg)/urdf/materials.xacro"/>
    <xacro:include filename="$(find turtlefied_pkg)/urdf/arm.trans"/>
    <xacro:include filename="$(find turtlefied_pkg)/urdf/arm.gazebo"/>

    <xacro:macro name="robot_arm" params="parent *origin">
        <!-- Links -->
        <link name="arm_link">
            <inertial>
                <mass value="0.02" />
                <inertia ixx="0.001" ixy="0.0" ixz="0.0"
                            iyy="0.001" iyz="0.0"
                            izz="0.001" />
            </inertial>
            <visual>
                <geometry>
                    <mesh filename="file://$(find turtlefied_pkg)/meshes/arm_base.stl" scale="0.001 0.001 0.001"/>
                </geometry>
                <material name="silver"/>
            </visual>
            <collision>
                <geometry>
                    <mesh filename="file://$(find turtlefied_pkg)/meshes/arm_base.stl" scale="0.001 0.001 0.001"/>
                </geometry>
            </collision>
        </link>

        <link name="arm_link_1">
            <inertial>
                <mass value="0.02" />
                <inertia ixx="0.001" ixy="0.0" ixz="0.0"
                        iyy="0.001" iyz="0.0"
                        izz="0.001" />
            </inertial>
            <visual>
                <geometry>
                <mesh filename="file://$(find turtlefied_pkg)/meshes/arm_shoulder.stl" scale="0.001 0.001 0.001"/>
                </geometry>
                <material name="silver"/>
            </visual>
            <collision>
                <geometry>
                <mesh filename="file://$(find turtlefied_pkg)/meshes/arm_shoulder.stl" scale="0.001 0.001 0.001"/>
                </geometry>
            </collision>
        </link>

        <link name="arm_link_2">
            <inertial>
                <mass value="0.02" />
                <inertia ixx="0.001" ixy="0.0" ixz="0.0"
                        iyy="0.001" iyz="0.0"
                        izz="0.001" />
            </inertial>
            <visual>
                <geometry>
                <mesh filename="file://$(find turtlefied_pkg)/meshes/arm_elbow.stl" scale="0.001 0.001 0.001"/>
                </geometry>
                <material name="silver"/>
            </visual>
            <collision>
                <geometry>
                <mesh filename="file://$(find turtlefied_pkg)/meshes/arm_elbow.stl" scale="0.001 0.001 0.001"/>
                </geometry>
            </collision>
        </link>

        <link name="arm_link_3">
            <inertial>
                <mass value="0.02" />
                <inertia ixx="0.001" ixy="0.0" ixz="0.0"
                        iyy="0.001" iyz="0.0"
                        izz="0.001" />
            </inertial>
            <visual>
                <geometry>
                <mesh filename="file://$(find turtlefied_pkg)/meshes/arm_forearm.stl" scale="0.001 0.001 0.001"/>
                </geometry>
                <material name="silver"/>
            </visual>
            <collision>
                <geometry>
                <mesh filename="file://$(find turtlefied_pkg)/meshes/arm_forearm.stl" scale="0.001 0.001 0.001"/>
                </geometry>
            </collision>
        </link>

        <link name="tool_link">
            <inertial>
                <mass value="0.02" />
                <inertia ixx="0.001" ixy="0.0" ixz="0.0"
                        iyy="0.001" iyz="0.0"
                        izz="0.001" />
            </inertial>
            <visual>
                <geometry>
                <mesh filename="file://$(find turtlefied_pkg)/meshes/arm_wrist.stl" scale="0.001 0.001 0.001"/>
                </geometry>
                <material name="silver"/>
            </visual>
            <collision>
                <geometry>
                <mesh filename="file://$(find turtlefied_pkg)/meshes/arm_wrist.stl" scale="0.001 0.001 0.001"/>
                </geometry>
            </collision>
        </link>

        <joint name="arm_joint" type="fixed">
            <xacro:insert_block name="origin"/>
            <parent link="${parent}"/>
            <child link="arm_link"/>
        </joint> 

        <joint name ="arm_joint_1" type="revolute">
            <parent link="arm_link"/>
            <child link = "arm_link_1"/>
            <origin xyz="0 0 0.0005" rpy="0 0 0" />
            <axis xyz="0 0 1"/>
            <limit upper="3.14" lower="-3.14" effort="30" velocity="10"/>
        </joint>

        <joint name="arm_joint_2" type="revolute">
            <parent link="arm_link_1" />
            <child link="arm_link_2" />
            <origin xyz="0 0 0.0855" rpy="0 0 0" />
            <axis xyz="0 1 0"/>
            <limit upper="1.57" lower="-1.57" effort="30" velocity="10"/>
            </joint>

        <joint name="arm_joint_3" type="revolute">
            <parent link="arm_link_2" />
            <child link="arm_link_3" />
            <origin xyz="0 -0.02 0.285" rpy="0 0 0" />
            <axis xyz="0 1 0"/>
            <limit upper="3.0" lower="0.0" effort="30" velocity="10"/>
            </joint>
        
        <joint name="arm_joint_4" type="revolute">
            <parent link="arm_link_3" />
            <child link="tool_link" />
            <origin xyz="0 -0.0225 0.225" rpy="0 0 0" />
            <axis xyz="0 1 0"/>
            <limit upper="1.57" lower="-1.57" effort="30" velocity="10"/>
        </joint>
    
    </xacro:macro>

</robot>