<?xml version="1.0"?>
<sdf version='1.6'>
  <world name='default'>
    <light name='sun' type='directional'>
      <cast_shadows>1</cast_shadows>
      <pose>0 0 10 0 -0 0</pose>
      <diffuse>0.8 0.8 0.8 1</diffuse>
      <specular>0.2 0.2 0.2 1</specular>
      <attenuation>
        <range>1000</range>
        <constant>0.9</constant>
        <linear>0.01</linear>
        <quadratic>0.001</quadratic>
      </attenuation>
      <direction>-0.5 0.1 -0.9</direction>
      <spot>
        <inner_angle>0</inner_angle>
        <outer_angle>0</outer_angle>
        <falloff>0</falloff>
      </spot>
    </light>
    <model name='ground_plane'>
      <static>1</static>
      <link name='link'>
        <collision name='collision'>
          <geometry>
            <plane>
              <normal>0 0 1</normal>
              <size>100 100</size>
            </plane>
          </geometry>
          <surface>
            <friction>
              <ode>
                <mu>100</mu>
                <mu2>50</mu2>
              </ode>
              <torsional>
                <ode/>
              </torsional>
            </friction>
            <contact>
              <ode/>
            </contact>
            <bounce/>
          </surface>
          <max_contacts>10</max_contacts>
        </collision>
        <visual name='visual'>
          <cast_shadows>0</cast_shadows>
          <geometry>
            <plane>
              <normal>0 0 1</normal>
              <size>100 100</size>
            </plane>
          </geometry>
          <material>
            <script>
              <uri>file://media/materials/scripts/gazebo.material</uri>
              <name>Gazebo/Grey</name>
            </script>
          </material>
        </visual>
        <self_collide>0</self_collide>
        <enable_wind>0</enable_wind>
        <kinematic>0</kinematic>
      </link>
    </model>
    <gravity>0 0 -9.8</gravity>
    <magnetic_field>6e-06 2.3e-05 -4.2e-05</magnetic_field>
    <atmosphere type='adiabatic'/>
    <physics type='ode'>
      <max_step_size>0.001</max_step_size>
      <real_time_factor>1</real_time_factor>
      <real_time_update_rate>1000</real_time_update_rate>
    </physics>
    <scene>
      <ambient>0.4 0.4 0.4 1</ambient>
      <background>0.7 0.7 0.7 1</background>
      <shadows>1</shadows>
    </scene>
    <wind/>
    <spherical_coordinates>
      <surface_model>EARTH_WGS84</surface_model>
      <latitude_deg>0</latitude_deg>
      <longitude_deg>0</longitude_deg>
      <elevation>0</elevation>
      <heading_deg>0</heading_deg>
    </spherical_coordinates>

    <model name="kitchen_dining">
      <static>1</static>
      <include>
        <uri>model://kitchen_dining</uri>
      </include>
    </model>

    <!-- turtlefied -->
    <model name="turtlefied">  
      <pose>-1.5 1.0 0.0 0.0 0.0 0.0</pose>

      <link name="base_footprint"/>

      <link name="base_link">
        <pose>0 0 0.04 0 0 0</pose>
        <inertial>
          <inertia>
            <ixx>4.2111447e-02</ixx>
            <ixy>0</ixy>
            <ixz>0</ixz>
            <iyy>4.2111447e-02</iyy>
            <iyz>0</iyz>
            <izz>7.5254874e-02</izz>
          </inertia>
          <mass>3.3729096e+00</mass>
        </inertial>
        <collision name="base_collision">
          <geometry>
            <mesh>
              <uri>model://meshes/turtlefied_base.dae</uri>
              <scale>0.01 0.01 0.01</scale>
            </mesh>
          </geometry>
        </collision>
        <visual name="base_visual">
          <geometry>
            <mesh>
              <uri>model://meshes/turtlefied_base.dae</uri>
              <scale>0.01 0.01 0.01</scale>
            </mesh>
          </geometry>
        </visual>
      </link>

      <link name="imu_link">
        <pose>0.032 0 0.33 0 0 0</pose>
        <sensor name="tb3_imu" type="imu">
          <always_on>true</always_on>
          <update_rate>200</update_rate>
          <imu>
            <angular_velocity>
              <x>
                <noise type="gaussian">
                  <mean>0.0</mean>
                  <stddev>2e-4</stddev>
                </noise>
              </x>
              <y>
                <noise type="gaussian">
                  <mean>0.0</mean>
                  <stddev>2e-4</stddev>
                </noise>
              </y>
              <z>
                <noise type="gaussian">
                  <mean>0.0</mean>
                  <stddev>2e-4</stddev>
                </noise>
              </z>
            </angular_velocity>
            <linear_acceleration>
              <x>
                <noise type="gaussian">
                  <mean>0.0</mean>
                  <stddev>1.7e-2</stddev>
                </noise>
              </x>
              <y>
                <noise type="gaussian">
                  <mean>0.0</mean>
                  <stddev>1.7e-2</stddev>
                </noise>
              </y>
              <z>
                <noise type="gaussian">
                  <mean>0.0</mean>
                  <stddev>1.7e-2</stddev>
                </noise>
              </z>
            </linear_acceleration>
          </imu>
          <plugin name="turtlebot3_imu" filename="libgazebo_ros_imu_sensor.so">
            <ros>
              <remapping>~/out:=imu</remapping>
            </ros>
          </plugin>
        </sensor>
      </link>

      <link name="base_scan">
        <pose>0 0 0.47 0 0 0</pose>
        <inertial>
          <inertia>
            <ixx>0.001</ixx>
            <ixy>0.000</ixy>
            <ixz>0.000</ixz>
            <iyy>0.001</iyy>
            <iyz>0.000</iyz>
            <izz>0.001</izz>
          </inertia>
          <mass>0.114</mass>
        </inertial>
        <collision name="lidar_sensor_collision">
          <geometry>
            <cylinder>
              <radius>0.0508</radius>
              <length>0.055</length>
            </cylinder>
          </geometry>
        </collision>
        <visual name="lidar_sensor_visual">
          <geometry>
            <mesh>
              <!-- <uri>model://meshes/lds.dae</uri> -->
              <uri>model://meshes/t_lds.dae</uri>
              <scale>0.001 0.001 0.001</scale>
            </mesh>
          </geometry>
          <material>
            <script>
              <uri>file://media/materials/scripts/gazebo.material</uri>
              <name>Gazebo/Grey</name>
            </script>
          </material>
        </visual>
        <sensor name="hls_lfcd_lds" type="ray">
          <always_on>true</always_on>
          <visualize>false</visualize>
          <update_rate>5</update_rate>
          <ray>
            <scan>
              <horizontal>
                <samples>360</samples>
                <resolution>1.000000</resolution>
                <min_angle>0.000000</min_angle>
                <max_angle>6.280000</max_angle>
              </horizontal>
            </scan>
            <range>
              <min>0.120000</min>
              <max>12.0</max> 
              <resolution>0.015000</resolution>
            </range>
            <noise>
              <type>gaussian</type>
              <mean>0.0</mean>
              <stddev>0.01</stddev>
            </noise>
          </ray>
          <plugin name="turtlebot3_laserscan" filename="libgazebo_ros_ray_sensor.so">
            <ros>
              <remapping>~/out:=scan</remapping>
            </ros>
            <output_type>sensor_msgs/LaserScan</output_type>
            <frame_name>base_scan</frame_name>
          </plugin>
        </sensor>
      </link>

      <link name="wheel_left_link">
        <pose>0.064 0.144 0.05715 -1.57 0 0</pose>
        <inertial>
          <inertia>
            <ixx>1.8158194e-03</ixx>
            <ixy>-9.3392e-12</ixy>
            <ixz>1.04909e-11</ixz>
            <iyy>3.2922126e-03</iyy>
            <iyz>5.75694e-11</iyz>
            <izz>1.8158194e-03</izz>
          </inertia>
          <mass>0.02</mass>
        </inertial>
        <collision name="wheel_left_collision">
          <geometry>
            <cylinder>
              <radius>0.055</radius>
              <length>0.033</length>
            </cylinder>
          </geometry>
          <surface>
            <!-- This friction pamareter don't contain reliable data!! -->
            <friction>
              <ode>
                <mu>100000</mu>
                <mu2>100000</mu2>
                <fdir1>0 0 0</fdir1>
                <slip1>0.0</slip1>
                <slip2>0.0</slip2>
              </ode>
            </friction>
            <contact>
              <ode>
                <soft_cfm>0</soft_cfm>
                <soft_erp>0.2</soft_erp>
                <kp>1e+6</kp>
                <kd>1</kd>
                <max_vel>0.01</max_vel>
                <min_depth>0.001</min_depth>
              </ode>
            </contact>
          </surface>
        </collision>
        <visual name="wheel_left_visual">
          <geometry>
            <mesh>
              <uri>model://meshes/t_wheel.dae</uri>
              <scale>0.001 0.001 0.001</scale>
            </mesh>
          </geometry>
        </visual>
      </link>

      <link name="wheel_right_link">
        <pose>0.064 -0.144 0.05715 -1.57 0 0</pose>
        <inertial>
          <inertia>
            <ixx>1.8158194e-03</ixx>
            <ixy>-9.3392e-12</ixy>
            <ixz>1.04909e-11</ixz>
            <iyy>3.2922126e-03</iyy>
            <iyz>5.75694e-11</iyz>
            <izz>1.8158194e-03</izz>
          </inertia>
          <mass>0.02</mass>
        </inertial>
        <collision name="wheel_right_collision">
          <geometry>
            <cylinder>
              <radius>0.055</radius>
              <length>0.033</length>
            </cylinder>
          </geometry>
          <surface>
            <!-- This friction pamareter don't contain reliable data!! -->
            <friction>
              <ode>
                <mu>100000</mu>
                <mu2>100000</mu2>
                <fdir1>0 0 0</fdir1>
                <slip1>0.0</slip1>
                <slip2>0.0</slip2>
              </ode>
            </friction>
            <contact>
              <ode>
                <soft_cfm>0</soft_cfm>
                <soft_erp>0.2</soft_erp>
                <kp>1e+6</kp>
                <kd>1</kd>
                <max_vel>0.01</max_vel>
                <min_depth>0.001</min_depth>
              </ode>
            </contact>
          </surface>
        </collision>
        <visual name="wheel_right_visual">
          <geometry>
            <mesh>
              <uri>model://meshes/t_wheel.dae</uri>
              <scale>0.001 0.001 0.001</scale>
            </mesh>
          </geometry>
        </visual>
      </link>

      <link name='caster_back_right_link'>
        <pose>-0.086 -0.064 0 0 0 0</pose>
        <inertial>
          <mass>0.009</mass>
          <inertia>
            <ixx>0.0001</ixx>
            <ixy>0.000</ixy>
            <ixz>0.000</ixz>
            <iyy>0.0001</iyy>
            <iyz>0.000</iyz>
            <izz>0.0001</izz>
          </inertia>
        </inertial>
        <collision name='collision_right'>
          <geometry>
            <sphere>
              <radius>0.0015</radius>
            </sphere>
          </geometry>
          <surface>
            <contact>
              <ode>
                <soft_cfm>0</soft_cfm>
                <soft_erp>0.2</soft_erp>
                <kp>1e+6</kp>
                <kd>1</kd>
                <max_vel>0.002</max_vel>
                <min_depth>0.001</min_depth>
              </ode>
            </contact>
          </surface>
        </collision>
      </link>

      <link name='caster_back_left_link'>
        <pose>-0.086 0.064 0 0 0 0</pose>
        <inertial>
          <mass>0.009</mass>
          <inertia>
            <ixx>0.0001</ixx>
            <ixy>0.000</ixy>
            <ixz>0.000</ixz>
            <iyy>0.0001</iyy>
            <iyz>0.000</iyz>
            <izz>0.0001</izz>
          </inertia>
        </inertial>
        <collision name='collision_left'>
          <geometry>
            <sphere>
              <radius>0.0015</radius>
            </sphere>
          </geometry>
          <surface>
            <contact>
              <ode>
                <soft_cfm>0</soft_cfm>
                <soft_erp>0.2</soft_erp>
                <kp>1e+6</kp>
                <kd>1</kd>
                <max_vel>0.002</max_vel>
                <min_depth>0.001</min_depth>
              </ode>
            </contact>
          </surface>
        </collision>
      </link>

      <link name='ballcaster_left_visual'>
        <pose>-0.086 0.064 0.039 0 0 1.57</pose>
        <visual name='l_caster'>
          <geometry>
            <mesh>
              <uri>model://meshes/rollerframe.dae</uri>
              <scale>0.001 0.001 0.001</scale>
            </mesh>
          </geometry>
        </visual>
      </link>

      <link name='ballcaster_right_visual'>
        <pose>-0.086 -0.064 0.039 0 0 1.57</pose>
        <visual name='r_caster'>
          <geometry>
            <mesh>
              <uri>model://meshes/rollerframe.dae</uri>
              <scale>0.001 0.001 0.001</scale>
            </mesh>
          </geometry>
        </visual>
      </link>

      <!-- Joints -->
      <joint name="base_joint" type="fixed">
        <parent>base_footprint</parent>
        <child>base_link</child>
      </joint>

      <joint name="wheel_left_joint" type="revolute">
        <parent>base_link</parent>
        <child>wheel_left_link</child>
        <axis>
          <xyz>0 0 1</xyz>
        </axis>
      </joint>

      <joint name="wheel_right_joint" type="revolute">
        <parent>base_link</parent>
        <child>wheel_right_link</child>
        <axis>
          <xyz>0 0 1</xyz>
        </axis>
      </joint>
 
      <joint name='caster_back_right_joint' type='ball'>
        <parent>base_link</parent>
        <child>caster_back_right_link</child>
      </joint>

      <joint name='caster_back_left_joint' type='ball'>
        <parent>base_link</parent>
        <child>caster_back_left_link</child>
      </joint>

      <joint name='casters_visuals_l_joint' type='fixed'>
        <parent>base_link</parent>
        <child>ballcaster_left_visual</child>
      </joint>

      <joint name='casters_visuals_r_joint' type='fixed'>
        <parent>base_link</parent>
        <child>ballcaster_right_visual</child>
      </joint>

      <joint name="imu_joint" type="fixed">
        <parent>base_link</parent>
        <child>imu_link</child>
        <axis>
          <xyz>0 0 1</xyz>
        </axis>
      </joint>  

      <joint name="lidar_joint" type="fixed">
        <parent>base_link</parent>
        <child>base_scan</child>
        <axis>
          <xyz>0 0 1</xyz>
        </axis>
      </joint>

      <joint name="structure_joint" type="fixed">
        <parent>base_link</parent>
        <child>structure_link</child>
      </joint>



      <!-- Gazebo Plugins -->
      <plugin name="turtlebot3_diff_drive" filename="libgazebo_ros_diff_drive.so">
        <ros>
          <!-- <namespace>/tb3</namespace> -->
        </ros>
        <update_rate>30</update_rate>
        <!-- wheels -->
        <left_joint>wheel_left_joint</left_joint>
        <right_joint>wheel_right_joint</right_joint>

        <!-- kinematics -->
        <wheel_separation>0.287</wheel_separation>
        <wheel_diameter>0.066</wheel_diameter>

        <!-- limits -->
        <max_wheel_torque>30</max_wheel_torque>
        <max_wheel_acceleration>2.0</max_wheel_acceleration>
        <command_topic>cmd_vel</command_topic>
        <!-- output -->
        <publish_odom>true</publish_odom>
        <publish_odom_tf>true</publish_odom_tf>
        <publish_wheel_tf>false</publish_wheel_tf>
        <odometry_topic>odom</odometry_topic>
        <odometry_frame>odom</odometry_frame>
        <robot_base_frame>base_footprint</robot_base_frame>
      </plugin>

      <plugin name="turtlebot3_joint_state" filename="libgazebo_ros_joint_state_publisher.so">
        <ros>
          <!-- <namespace>/tb3</namespace> -->
          <remapping>~/out:=joint_states</remapping>
        </ros>
        <update_rate>30</update_rate>
        <joint_name>wheel_left_joint</joint_name>
        <joint_name>wheel_right_joint</joint_name>
        
        <!-- arm_joints -->
        <!-- <joint_name>arm_joint_1</joint_name>
        <joint_name>arm_joint_2</joint_name>
        <joint_name>arm_joint_3</joint_name>
      </plugin>    
      
      <link name="structure_link">
        <pose>0.115 0 0.10 0 -0.35 0</pose>
        <inertial>
          <inertia>
            <ixx>0.001</ixx>
            <ixy>0.000</ixy>
            <ixz>0.000</ixz>
            <iyy>0.001</iyy>
            <iyz>0.000</iyz>
            <izz>0.001</izz>
          </inertia>
          <mass>0.005</mass>
        </inertial>
        <visual name="structure_visual">
          <pose>0 0 0 0 0 -1.57</pose>
          <geometry>
            <mesh>
              <uri>model://meshes/t_st01.dae</uri>
              <scale>0.001 0.001 0.001</scale>
            </mesh>
          </geometry>
        </visual>
        <collision name="structure_collision">
          <pose>0 0 0 0 0 -1.57</pose>
          <geometry>
            <mesh>
              <uri>model://meshes/t_st01.dae</uri>
              <scale>0.001 0.001 0.001</scale>
            </mesh>
          </geometry>
        </collision>
         <!-- mimic structure sensor -->
        <sensor name="depth_camera" type="depth">
          <always_on>1</always_on>
          <update_rate>30</update_rate>
          <camera name="structure_sensor">
            <image>
              <width>640</width>
              <height>480</height>       
            </image>
          </camera>
          <plugin name="depth_camera_driver" filename="libgazebo_ros_camera.so">
            <ros>
            </ros>
            <update_rate>30</update_rate>
            <camera_name>structure_sensor</camera_name>
            <frame_name>camera_depth_optical_frame</frame_name>
            <hack_baseline>0.07</hack_baseline>
            <min_depth>0.001</min_depth>
          </plugin>
        </sensor>
      </link>

      <model name="arm">
        <!-- arm plugins -->
        <plugin filename="libgazebo_ros2_control.so" name="gazebo_ros2_control">
          <robot_param>robot_description</robot_param>
          <robot_param_node>robot_state_publisher</robot_param_node>
          <parameters>
            <-- (controller.yaml) -->
          </parameters>
          <ros>     
          </ros>
        </plugin>

        <!-- <transmission name="joint1_tran">
          <type>transmission_interface/SimpleTransmission</type>
          <joint name="arm_joint_1">
            <hardwareInterface>hardware_interface/EffortJointInterface</hardwareInterface>
          </joint>
          <actuator name="joint1_actr">
            <hardwareInterface>hardware_interface/EffortJointInterface</hardwareInterface>
            <mechanicalReduction>1</mechanicalReduction>
          </actuator>
        </transmission>
        <transmission name="joint2_tran">
          <type>transmission_interface/SimpleTransmission</type>
          <joint name="arm_joint_2">
            <hardwareInterface>hardware_interface/EffortJointInterface</hardwareInterface>
          </joint>
          <actuator name="joint2_actr">
            <hardwareInterface>hardware_interface/EffortJointInterface</hardwareInterface>
            <mechanicalReduction>1</mechanicalReduction>
          </actuator>
        </transmission>
        <transmission name="joint3_tran">
          <type>transmission_interface/SimpleTransmission</type>
          <joint name="arm_joint_3">
            <hardwareInterface>hardware_interface/EffortJointInterface</hardwareInterface>
          </joint>
          <actuator name="joint3_actr">
            <hardwareInterface>hardware_interface/EffortJointInterface</hardwareInterface>
            <mechanicalReduction>1</mechanicalReduction>
          </actuator>
        </transmission>
        <transmission name="joint4_tran">
          <type>transmission_interface/SimpleTransmission</type>
          <joint name="arm_joint_4">
            <hardwareInterface>hardware_interface/EffortJointInterface</hardwareInterface>
          </joint>
          <actuator name="joint4_actr">
            <hardwareInterface>hardware_interface/EffortJointInterface</hardwareInterface>
            <mechanicalReduction>1</mechanicalReduction>
          </actuator>
        </transmission> -->

        <link name="arm_link">
          <pose>0 0 0.954 0 0 0</pose>
          <inertial>
            <mass>0.002</mass>
            <inertia>
              <ixx>0.000322</ixx>
              <ixy>0.000371</ixy>
              <ixz>0.000693</ixz>
              <iyy>0.001</iyy>
              <iyz>0.000</iyz>
              <izz>0.001</izz>
            </inertia>
          </inertial>
          <visual name="arm_visual">
            <geometry>
              <mesh>
                <uri>model://meshes/t_arm_base.dae</uri>
                <scale>0.001 0.001 0.001</scale>
              </mesh>
            </geometry>
          </visual>
          <collision name="arm_collision">
            <geometry>
              <mesh>
                <uri>model://meshes/t_arm_base.dae</uri>
                <scale>0.001 0.001 0.001</scale>
              </mesh>
            </geometry>
          </collision>
        </link>

        <link name="arm_link_1">
          <pose>0 0 0.9545 0 0 0</pose>
          <inertial>
            <mass>0.001</mass>
            <inertia>
              <ixx>0.002279</ixx>
              <ixy>0.003728</ixy>
              <ixz>0.003555</ixz>
              <iyy>0.001</iyy>
              <iyz>0.000</iyz>
              <izz>0.001</izz>
            </inertia>
          </inertial>
          <visual name="arm_link_1_visual">
            <geometry>
              <mesh>
                <uri>model://meshes/t_arm_link_1.dae</uri>
                <scale>0.001 0.001 0.001</scale>
              </mesh>
            </geometry>
          </visual>
          <collision name="arm_link_1_collision">
            <geometry>
              <mesh>
                <uri>model://meshes/t_arm_link_1.dae</uri>
                <scale>0.001 0.001 0.001</scale>
              </mesh>
            </geometry>
          </collision>
          <mu1>0.2</mu1>
          <mu2>0.2</mu2>
          <self_collide>true</self_collide>
        </link>

        <link name="arm_link_2">
          <pose>0 0 1.04 0 0 0</pose>
          <inertial>
            <mass>0.001</mass>
            <inertia>
              <ixx>0.002279</ixx>
              <ixy>0.003728</ixy>
              <ixz>0.003555</ixz>
              <iyy>0.001</iyy>
              <iyz>0.000</iyz>
              <izz>0.001</izz>
            </inertia>
          </inertial>
          <visual name="arm_link_2_visual">
            <geometry>
              <mesh>
                <uri>model://meshes/t_arm_link_2.dae</uri>
                <scale>0.001 0.001 0.001</scale>
              </mesh>
            </geometry>
          </visual>
          <collision name="arm_link_2_collision">
            <geometry>
              <mesh>
                <uri>model://meshes/t_arm_link_2.dae</uri>
                <scale>0.001 0.001 0.001</scale>
              </mesh>
            </geometry>
          </collision>
          <mu1>0.2</mu1>
          <mu2>0.2</mu2>
          <self_collide>true</self_collide>
        </link>

        <link name="arm_link_3">
          <pose>0 -0.02 1.325 0 0 0</pose>
          <inertial>
            <mass>0.001</mass>
            <inertia>
              <ixx>0.002279</ixx>
              <ixy>0.003728</ixy>
              <ixz>0.003555</ixz>
              <iyy>0.001</iyy>
              <iyz>0.000</iyz>
              <izz>0.001</izz>
            </inertia>
          </inertial>
          <visual name="arm_link_3_visual">
            <geometry>
              <mesh>
                <uri>model://meshes/t_arm_link_3.dae</uri>
                <scale>0.001 0.001 0.001</scale>
              </mesh>
            </geometry>
          </visual>
          <collision name="arm_link_3_collision">
            <geometry>
              <mesh>
                <uri>model://meshes/t_arm_link_3.dae</uri>
                <scale>0.001 0.001 0.001</scale>
              </mesh>
            </geometry>
          </collision>
          <mu1>0.2</mu1>
          <mu2>0.2</mu2>
          <self_collide>true</self_collide>
        </link>

        <link name="tool_link">
          <pose>0 -0.045 1.55 0 0 0</pose>
          <inertial>
            <mass>0.0005</mass>
            <inertia>
              <ixx>0.002279</ixx>
              <ixy>0.003728</ixy>
              <ixz>0.003555</ixz>
              <iyy>0.001</iyy>
              <iyz>0.000</iyz>
              <izz>0.001</izz>
            </inertia>
          </inertial>
          <visual name="tool_visual">
            <geometry>
              <mesh>
                <uri>model://meshes/t_tool_holder.dae</uri>
                <scale>0.001 0.001 0.001</scale>
              </mesh>
            </geometry>
          </visual>
          <collision name="tool_collision">
            <geometry>
              <mesh>
                <uri>model://meshes/t_tool_holder.dae</uri>
                <scale>0.001 0.001 0.001</scale>
              </mesh>
            </geometry>
          </collision>
          <mu1>0.2</mu1>
          <mu2>0.2</mu2>
          <self_collide>true</self_collide>
        </link>

        <joint name="arm_joint_1" type="revolute">
          <parent>arm_link</parent>
          <child>arm_link_1</child>
          <axis>
            <xyz>0 0 1</xyz>
            <limit>
              <lower>-3.14</lower> 
              <upper>3.14</upper>  
              <effort>30.0</effort>
              <velocity>10.0</velocity> 
            </limit>
          </axis>
          <mu1>0.2</mu1>
          <mu2>0.2</mu2>
          <self_collide>true</self_collide>
        </joint>

        <joint name="arm_joint_2" type="revolute">
          <parent>arm_link_1</parent>
          <child>arm_link_2</child>
          <axis>
            <xyz>0 1 0</xyz>
            <limit>
              <lower>-1.57</lower> 
              <upper>1.57</upper>  
              <effort>30.0</effort>
              <velocity>10.0</velocity> 
            </limit>
          </axis>
          <mu1>0.2</mu1>
          <mu2>0.2</mu2>
          <self_collide>true</self_collide>
        </joint>

        <joint name="arm_joint_3" type="revolute">
          <parent>arm_link_2</parent>
          <child>arm_link_3</child>
          <axis>
            <xyz>0 1 0</xyz>
            <limit>
              <lower>0.00</lower> 
              <upper>3.0</upper>  
              <effort>30.0</effort>
              <velocity>10.0</velocity> 
            </limit>
          </axis>
          <mu1>0.2</mu1>
          <mu2>0.2</mu2>
          <self_collide>true</self_collide>
        </joint>

        <joint name="arm_joint_4" type="revolute">
          <parent>arm_link_3</parent>
          <child>tool_link</child>
          <axis>
            <xyz>0 1 0</xyz>
            <limit>
              <lower>-1.57</lower> 
              <upper>1.57</upper>  
              <effort>30.0</effort>
              <velocity>10.0</velocity> 
            </limit>
          </axis>
        </joint>

        <joint name="realsense_joint" type="fixed">
          <parent>tool_link</parent>
          <child>realsense_bottom_screw_frame</child>
        </joint>

        <link name="realsense_bottom_screw_frame">
          <pose>0 -0.045 1.61 0 -1.57 0</pose>
          <visual name="realsense_link_visual">
            <pose>0 0 -0.015 0 0 1.57</pose>
            <geometry>
              <mesh>
                <uri>model://meshes/d435i.dae</uri>
              </mesh>
            </geometry>
          </visual>
          <collision name="realsense_link_collision">
            <pose>0 0 0 -1.57 0 1.57</pose>
            <geometry>
              <box>
                <size>0.090 0.025 0.025</size>
              </box>
            </geometry>
          </collision>
          <inertial>
            <inertia>
              <ixx>0.001</ixx>
              <ixy>0.000</ixy>
              <ixz>0.000</ixz>
              <iyy>0.001</iyy>
              <iyz>0.000</iyz>
              <izz>0.001</izz>
            </inertia>
            <mass>0.001</mass>
          </inertial>
          <sensor name="cameradepth" type="depth">
            <camera name="camera">
              <horizontal_fov>1.57</horizontal_fov>
              <image>
                <width>640</width>
                <height>360</height>
              </image>
              <clip>
                <near>0.1</near>
                <far>100</far>
              </clip>
              <noise>
                <type>gaussian</type>
                <mean>0.0</mean>
                <stddev>0.100</stddev>
              </noise>
            </camera>
            <always_on>1</always_on>
            <update_rate>30</update_rate>
            <visualize>0</visualize>
          </sensor>
          <sensor name="cameracolor" type="camera">
            <camera name="camera">
              <horizontal_fov>1.57</horizontal_fov>
              <image>
                <width>640</width>
                <height>360</height>
                <format>RGB_INT8</format>
              </image>
              <clip>
                <near>0.1</near>
                <far>100</far>
              </clip>
              <noise>
                <type>gaussian</type>
                <mean>0.0</mean>
                <stddev>0.007</stddev>
              </noise>
            </camera>
            <always_on>1</always_on>
            <update_rate>30</update_rate>
            <visualize>1</visualize>
          </sensor>
          <sensor name="cameraired1" type="camera">
            <camera name="camera">
              <horizontal_fov>1.57</horizontal_fov>
              <image>
                <width>640</width>
                <height>360</height>
                <format>L_INT8</format>
              </image>
              <clip>
                <near>0.1</near>
                <far>100</far>
              </clip>
              <noise>
                <type>gaussian</type>
                <mean>0.0</mean>
                <stddev>0.05</stddev>
              </noise>
            </camera>
            <always_on>1</always_on>
            <update_rate>1</update_rate>
            <visualize>0</visualize>
          </sensor>
          <sensor name="cameraired2" type="camera">
            <camera name="camera">
              <horizontal_fov>1.57</horizontal_fov>
              <image>
                <width>640</width>
                <height>360</height>
                <format>L_INT8</format>
              </image>
              <clip>
                <near>0.1</near>
                <far>100</far>
              </clip>
              <noise>
                <type>gaussian</type>
                <mean>0.0</mean>
                <stddev>0.05</stddev>
              </noise>
            </camera>
            <always_on>1</always_on>
            <update_rate>1</update_rate>
            <visualize>0</visualize>
          </sensor>
        </link>

        <plugin name="camera" filename="librealsense_gazebo_plugin.so">
          <prefix>camera</prefix>
          <depthUpdateRate>30.0</depthUpdateRate>
          <colorUpdateRate>30.0</colorUpdateRate>
          <infraredUpdateRate>1.0</infraredUpdateRate>
          <depthTopicName>realsense/image_raw</depthTopicName>
          <depthCameraInfoTopicName>realsense/depth/camera_info</depthCameraInfoTopicName>
          <colorTopicName>realsense/color/image_raw</colorTopicName>
          <colorCameraInfoTopicName>realsense/color/camera_info</colorCameraInfoTopicName>
          <infrared1TopicName>realsense/infra1/image_raw</infrared1TopicName>
          <infrared1CameraInfoTopicName>realsense/infra1/camera_info</infrared1CameraInfoTopicName>
          <infrared2TopicName>realsense/infra2/image_raw</infrared2TopicName>
          <infrared2CameraInfoTopicName>realsense/infra2/camera_info</infrared2CameraInfoTopicName>
          <colorOpticalframeName>realsense_color_optical_frame</colorOpticalframeName>
          <depthOpticalframeName>realsense_depth_optical_frame</depthOpticalframeName>
          <infrared1OpticalframeName>realsense_left_ir_optical_frame</infrared1OpticalframeName>
          <infrared2OpticalframeName>realsense_right_ir_optical_frame</infrared2OpticalframeName>
          <rangeMinDepth>0.3</rangeMinDepth>
          <rangeMaxDepth>3.0</rangeMaxDepth>
          <pointCloud>true</pointCloud>
          <pointCloudTopicName>realsense/depth/points</pointCloudTopicName>
          <pointCloudCutoff>0.3</pointCloudCutoff>
        </plugin>
      </model>

      <joint name="arm_joint" type="fixed">
        <parent>base_link</parent> 
        <child>arm::arm_link</child>
      </joint>

    </model>

  </world>
</sdf>