<?xml version="1.0"?>
<robot xmlns:xacro="http://www.ros.org/wiki/xacro" name="arm">
    <xacro:arg name="is_sim" default="true"/>
    <xacro:include filename="$(find modarm_controller_pkg)/urdf/arm_gazebo.xacro" />
    <xacro:include filename="$(find modarm_controller_pkg)/urdf/arm_ros2_control.xacro" />
    <xacro:property name="PI" value="3.14159265359" />
    <xacro:property name="effort" value="30.0" />
    <xacro:property name="velocity" value="10.0" />
    <xacro:macro name="default_inertial" params="mass">
        <inertial>
            <origin xyz="0 0 0" rpy="0 0 0"/>
            <mass value="${mass}" />
            <inertia ixx="1.0" ixy="0.0" ixz="0.0"
                        iyy="1.0" iyz="0.0"
                        izz="1.0" />
        </inertial>
    </xacro:macro>
    <xacro:macro name="default_transmission" params="number">
        <transmission name="transmission_${number}">
            <plugin>transmission_interface/SimpleTransmission</plugin>
            <actuator name="motor_${number}" role="actuator1"/>
            <joint name="arm_joint_${number}"    role="joint1">
                <mechanical_reduction>1.0</mechanical_reduction>
            </joint>
        </transmission>
    </xacro:macro>

    <!-- Links -->
    <link name="base_link"/>    
    <link name="arm_link">
        <xacro:default_inertial mass="1.0"/>
        <inertial>
            <mass value="0.02" />
            <inertia ixx="0.001" ixy="0.0" ixz="0.0"
                        iyy="0.001" iyz="0.0"
                        izz="0.001" />
        </inertial>
        <visual>
            <geometry>
                <mesh filename="file://$(find turtlefied_pkg)/meshes/stl/arm_base.stl" scale="0.001 0.001 0.001"/>
            </geometry>
            <material name="silver"/>
        </visual>
        <collision>
            <geometry>
                <mesh filename="file://$(find turtlefied_pkg)/meshes/stl/arm_base.stl" scale="0.001 0.001 0.001"/>
            </geometry>
        </collision>
    </link>

    <link name="arm_link_1">
        <xacro:default_inertial mass="0.1"/>
        <inertial>
            <mass value="0.02" />
            <inertia ixx="0.001" ixy="0.0" ixz="0.0"
                    iyy="0.001" iyz="0.0"
                    izz="0.001" />
        </inertial>
        <visual>
            <geometry>
            <mesh filename="file://$(find turtlefied_pkg)/meshes/stl/arm_shoulder.stl" scale="0.001 0.001 0.001"/>
            </geometry>
            <material name="silver"/>
        </visual>
        <collision>
            <geometry>
            <mesh filename="file://$(find turtlefied_pkg)/meshes/stl/arm_shoulder.stl" scale="0.001 0.001 0.001"/>
            </geometry>
        </collision>
    </link>

    <link name="arm_link_2">
        <xacro:default_inertial mass="0.1"/>
        <inertial>
            <mass value="0.02" />
            <inertia ixx="0.001" ixy="0.0" ixz="0.0"
                    iyy="0.001" iyz="0.0"
                    izz="0.001" />
        </inertial>
        <visual>
            <geometry>
            <mesh filename="file://$(find turtlefied_pkg)/meshes/stl/arm_elbow.stl" scale="0.001 0.001 0.001"/>
            </geometry>
            <material name="silver"/>
        </visual>
        <collision>
            <geometry>
            <mesh filename="file://$(find turtlefied_pkg)/meshes/stl/arm_elbow.stl" scale="0.001 0.001 0.001"/>
            </geometry>
        </collision>
    </link>

    <link name="arm_link_3">
        <xacro:default_inertial mass="0.1"/>
        <inertial>
            <mass value="0.02" />
            <inertia ixx="0.001" ixy="0.0" ixz="0.0"
                    iyy="0.001" iyz="0.0"
                    izz="0.001" />
        </inertial>
        <visual>
            <geometry>
            <mesh filename="file://$(find turtlefied_pkg)/meshes/stl/arm_forearm.stl" scale="0.001 0.001 0.001"/>
            </geometry>
            <material name="silver"/>
        </visual>
        <collision>
            <geometry>
            <mesh filename="file://$(find turtlefied_pkg)/meshes/stl/arm_forearm.stl" scale="0.001 0.001 0.001"/>
            </geometry>
        </collision>
    </link>

    <link name="tool_link">
        <xacro:default_inertial mass="0.02"/>
        <inertial>
            <mass value="0.02" />
            <inertia ixx="0.001" ixy="0.0" ixz="0.0"
                    iyy="0.001" iyz="0.0"
                    izz="0.001" />
        </inertial>
        <visual>
            <geometry>
            <mesh filename="file://$(find turtlefied_pkg)/meshes/stl/arm_wrist.stl" scale="0.001 0.001 0.001"/>
            </geometry>
            <material name="silver"/>
        </visual>
        <collision>
            <geometry>
            <mesh filename="file://$(find turtlefied_pkg)/meshes/stl/arm_wrist.stl" scale="0.001 0.001 0.001"/>
            </geometry>
        </collision>
    </link>

    <joint name="arm_joint" type="fixed">
        <parent link="base_link"/>
        <child link="arm_link"/>
    </joint> 

    <joint name ="arm_joint_1" type="revolute">
        <parent link="arm_link"/>
        <child link = "arm_link_1"/>
        <origin xyz="0 0 0.0005" rpy="0 0 0" />
        <axis xyz="0 0 1"/>
        <limit upper="${PI}" lower="0.0" effort="30" velocity="10"/>
    </joint>

    <joint name="arm_joint_2" type="revolute">
        <parent link="arm_link_1" />
        <child link="arm_link_2" />
        <origin xyz="0 0 0.0855" rpy="0 0 0" />
        <axis xyz="0 1 0"/>
        <limit upper="${PI}" lower="0.0" effort="30" velocity="10"/>
        </joint>

    <joint name="arm_joint_3" type="revolute">
        <parent link="arm_link_2" />
        <child link="arm_link_3" />
        <origin xyz="0 -0.02 0.285" rpy="0 0 0" />
        <axis xyz="0 1 0"/>
        <limit upper="${PI}" lower="0.0" effort="30" velocity="10"/>
        </joint>
    
    <joint name="arm_joint_4" type="revolute">
        <parent link="arm_link_3" />
        <child link="tool_link" />
        <origin xyz="0 -0.0225 0.225" rpy="0 0 0" />
        <axis xyz="0 1 0"/>
        <limit upper="${PI}" lower="0.0" effort="30" velocity="10"/>
    </joint>
    <xacro:default_transmission number="1"/>
    <xacro:default_transmission number="2"/>
    <xacro:default_transmission number="3"/>
    <xacro:default_transmission number="4"/>

</robot>